Workbook

Sheet วิธีใช้
B2: วิธีใช้ระบบออกใบแจ้งหนี้ (อพาร์ทเม้นท์ มั่งมีทวีสุข)
B4: ทำทุกเดือน — แค่ 3 ขั้นตอน
B5: ขั้นที่ 1 ไปที่ชีต "บันทึกค่าน้ำไฟ" → กรอกเฉพาะ "ช่องสีเหลือง" คือ ไฟ-เลขใหม่ และ น้ำ-เลขใหม่ ของแต่ละห้อง
B6: (ค่าไฟ ค่าน้ำ และยอดรวม ระบบคำนวณให้เองอัตโนมัติ รวมถึงค่าน้ำขั้นต่ำ 100 บาท — ไม่ต้องคิดเลขเอง)
B7: ขั้นที่ 2 แก้ "เดือนที่แจ้งหนี้" และ "เดือนค่าน้ำ-ไฟ" ที่มุมบนของชีต ให้ตรงกับเดือนปัจจุบัน
B8: ขั้นที่ 3 ไปที่ชีต "ใบแจ้งหนี้" → เลือกห้องจากช่องสีเหลืองมุมขวา → ข้อมูลขึ้นครบทันที → กด Ctrl+P เพื่อพิมพ์ หรือบันทึกเป็น PDF
B10: สิ้นเดือน (เริ่มเดือนใหม่)
B11: ในชีต "บันทึกค่าน้ำไฟ" : เลือกตัวเลขทั้งคอลัมน์ "เลขใหม่" (ทั้งไฟและน้ำ) → Copy → คลิกขวาที่ "เลขเก่า" → วางแบบ "ค่า (Values / 123)"
B12: จากนั้นลบตัวเลขในคอลัมน์ "เลขใหม่" ออก เพื่อเริ่มกรอกของเดือนถัดไป
B14: ข้อควรรู้
B15: • สีเหลือง = พนักงานกรอกเอง สีเทา = ระบบคำนวณอัตโนมัติ (ห้ามแก้ จะทำให้สูตรเสีย)
B16: • แก้ข้อมูลผู้เช่า / ค่าเช่า / ค่าส่วนกลาง / เรทค่าน้ำ-ไฟ / ค่าน้ำขั้นต่ำ ได้ที่ชีต "ผู้เช่า"
... B19: • ยอดเงินเป็นตัวหนังสือ (บาทถ้วน) ใช้ฟังก์ชัน BAHTTEXT ของ Excel ภาษาไทย — หากขึ้น #NAME? แปลว่าเครื่องนั้นไม่ใช่ Excel ภาษาไทย

Sheet บันทึกค่าน้ำไฟ
B1: เดือนที่แจ้งหนี้ (ค่าเช่า) : | D1: พฤษภาคม 2569 | F1: ช่องสีเหลือง = พนักงานกรอก | ช่องสีเทา = คำนวณอัตโนมัติ (ห้ามแก้)
B2: เดือนค่าน้ำ-ค่าไฟ : | D2: เมษายน 2569
A4: ห้อง | B4: ชื่อผู้เช่า | C4: ค่าเช่า | D4: ค่าเฟอร์ | E4: ไฟ-เลขเก่า | F4: ไฟ-เลขใหม่ | G4: หน่วยไฟ | H4: ค่าไฟ | I4: น้ำ-เลขเก่า | J4: น้ำ-เลขใหม่ | K4: หน่วยน้ำ | L4: ค่าน้ำ | M4: ส่วนกลาง | N4: ขยะ | O4: อื่นๆ | P4: รวมทั้งสิ้น
A5: 201 | B5: =IFERROR(VLOOKUP(A5,ผู้เช่า!$A:$N,2,0),"") | C5: =IFERROR(VLOOKUP(A5,ผู้เช่า!$A:$N,5,0),0) | D5: =IFERROR(VLOOKUP(A5,ผู้เช่า!$A:$N,6,0),0) | E5: 4099 | F5: 4191 | G5: =IF(F5="","",F5-E5) | H5: =IF(G5="","",G5*IFERROR(VLOOKUP(A5,ผู้เช่า!$A:$N,9,0),0)) | I5: 93 | J5: 97 | K5: =IF(J5="","",J5-I5) | L5: =IF(K5="","",MAX(K5*IFERROR(VLOOKUP(A5,ผู้เช่า!$A:$N,10,0),0),IFERROR(VLOOKUP(A5,ผู้เช่า!$A:$N,14,0),0))) | M5: =IFERROR(VLOOKUP(A5,ผู้เช่า!$A:$N,7,0),0) | N5: =IFERROR(VLOOKUP(A5,ผู้เช่า!$A:$N,8,0),0) | O5: 0 | P5: =SUM(C5,D5,H5,L5,M5,N5,O5)
A6: 202 | B6: =IFERROR(VLOOKUP(A6,ผู้เช่า!$A:$N,2,0),"") | C6: =IFERROR(VLOOKUP(A6,ผู้เช่า!$A:$N,5,0),0) | D6: =IFERROR(VLOOKUP(A6,ผู้เช่า!$A:$N,6,0),0) | G6: =IF(F6="","",F6-E6) | H6: =IF(G6="","",G6*IFERROR(VLOOKUP(A6,ผู้เช่า!$A:$N,9,0),0)) | K6: =IF(J6="","",J6-I6) | L6: =IF(K6="","",MAX(K6*IFERROR(VLOOKUP(A6,ผู้เช่า!$A:$N,10,0),0),IFERROR(VLOOKUP(A6,ผู้เช่า!$A:$N,14,0),0))) | M6: =IFERROR(VLOOKUP(A6,ผู้เช่า!$A:$N,7,0),0) | N6: =IFERROR(VLOOKUP(A6,ผู้เช่า!$A:$N,8,0),0) | O6: 0 | P6: =SUM(C6,D6,H6,L6,M6,N6,O6)
A7: 203 | B7: =IFERROR(VLOOKUP(A7,ผู้เช่า!$A:$N,2,0),"") | C7: =IFERROR(VLOOKUP(A7,ผู้เช่า!$A:$N,5,0),0) | D7: =IFERROR(VLOOKUP(A7,ผู้เช่า!$A:$N,6,0),0) | E7: 8223 | F7: 8304 | G7: =IF(F7="","",F7-E7) | H7: =IF(G7="","",G7*IFERROR(VLOOKUP(A7,ผู้เช่า!$A:$N,9,0),0)) | I7: 484 | J7: 491 | K7: =IF(J7="","",J7-I7) | L7: =IF(K7="","",MAX(K7*IFERROR(VLOOKUP(A7,ผู้เช่า!$A:$N,10,0),0),IFERROR(VLOOKUP(A7,ผู้เช่า!$A:$N,14,0),0))) | M7: =IFERROR(VLOOKUP(A7,ผู้เช่า!$A:$N,7,0),0) | N7: =IFERROR(VLOOKUP(A7,ผู้เช่า!$A:$N,8,0),0) | O7: 0 | P7: =SUM(C7,D7,H7,L7,M7,N7,O7)
A8: 204 | B8: =IFERROR(VLOOKUP(A8,ผู้เช่า!$A:$N,2,0),"") | C8: =IFERROR(VLOOKUP(A8,ผู้เช่า!$A:$N,5,0),0) | D8: =IFERROR(VLOOKUP(A8,ผู้เช่า!$A:$N,6,0),0) | E8: 6782 | F8: 6860 | G8: =IF(F8="","",F8-E8) | H8: =IF(G8="","",G8*IFERROR(VLOOKUP(A8,ผู้เช่า!$A:$N,9,0),0)) | I8: 549 | J8: 553 | K8: =IF(J8="","",J8-I8) | L8: =IF(K8="","",MAX(K8*IFERROR(VLOOKUP(A8,ผู้เช่า!$A:$N,10,0),0),IFERROR(VLOOKUP(A8,ผู้เช่า!$A:$N,14,0),0))) | M8: =IFERROR(VLOOKUP(A8,ผู้เช่า!$A:$N,7,0),0) | N8: =IFERROR(VLOOKUP(A8,ผู้เช่า!$A:$N,8,0),0) | O8: 0 | P8: =SUM(C8,D8,H8,L8,M8,N8,O8)
A9: 205 | B9: =IFERROR(VLOOKUP(A9,ผู้เช่า!$A:$N,2,0),"") | C9: =IFERROR(VLOOKUP(A9,ผู้เช่า!$A:$N,5,0),0) | D9: =IFERROR(VLOOKUP(A9,ผู้เช่า!$A:$N,6,0),0) | G9: =IF(F9="","",F9-E9) | H9: =IF(G9="","",G9*IFERROR(VLOOKUP(A9,ผู้เช่า!$A:$N,9,0),0)) | K9: =IF(J9="","",J9-I9) | L9: =IF(K9="","",MAX(K9*IFERROR(VLOOKUP(A9,ผู้เช่า!$A:$N,10,0),0),IFERROR(VLOOKUP(A9,ผู้เช่า!$A:$N,14,0),0))) | M9: =IFERROR(VLOOKUP(A9,ผู้เช่า!$A:$N,7,0),0) | N9: =IFERROR(VLOOKUP(A9,ผู้เช่า!$A:$N,8,0),0) | O9: 0 | P9: =SUM(C9,D9,H9,L9,M9,N9,O9)
A10: 206 | B10: =IFERROR(VLOOKUP(A10,ผู้เช่า!$A:$N,2,0),"") | C10: =IFERROR(VLOOKUP(A10,ผู้เช่า!$A:$N,5,0),0) | D10: =IFERROR(VLOOKUP(A10,ผู้เช่า!$A:$N,6,0),0) | E10: 399 | F10: 433 | G10: =IF(F10="","",F10-E10) | H10: =IF(G10="","",G10*IFERROR(VLOOKUP(A10,ผู้เช่า!$A:$N,9,0),0)) | I10: 721 | J10: 729 | K10: =IF(J10="","",J10-I10) | L10: =IF(K10="","",MAX(K10*IFERROR(VLOOKUP(A10,ผู้เช่า!$A:$N,10,0),0),IFERROR(VLOOKUP(A10,ผู้เช่า!$A:$N,14,0),0))) | M10: =IFERROR(VLOOKUP(A10,ผู้เช่า!$A:$N,7,0),0) | N10: =IFERROR(VLOOKUP(A10,ผู้เช่า!$A:$N,8,0),0) | O10: 0 | P10: =SUM(C10,D10,H10,L10,M10,N10,O10)
A11: 207 | B11: =IFERROR(VLOOKUP(A11,ผู้เช่า!$A:$N,2,0),"") | C11: =IFERROR(VLOOKUP(A11,ผู้เช่า!$A:$N,5,0),0) | D11: =IFERROR(VLOOKUP(A11,ผู้เช่า!$A:$N,6,0),0) | E11: 17657 | F11: 18019 | G11: =IF(F11="","",F11-E11) | H11: =IF(G11="","",G11*IFERROR(VLOOKUP(A11,ผู้เช่า!$A:$N,9,0),0)) | I11: 436 | J11: 437 | K11: =IF(J11="","",J11-I11) | L11: =IF(K11="","",MAX(K11*IFERROR(VLOOKUP(A11,ผู้เช่า!$A:$N,10,0),0),IFERROR(VLOOKUP(A11,ผู้เช่า!$A:$N,14,0),0))) | M11: =IFERROR(VLOOKUP(A11,ผู้เช่า!$A:$N,7,0),0) | N11: =IFERROR(VLOOKUP(A11,ผู้เช่า!$A:$N,8,0),0) | O11: 0 | P11: =SUM(C11,D11,H11,L11,M11,N11,O11)
A12: 208 | B12: =IFERROR(VLOOKUP(A12,ผู้เช่า!$A:$N,2,0),"") | C12: =IFERROR(VLOOKUP(A12,ผู้เช่า!$A:$N,5,0),0) | D12: =IFERROR(VLOOKUP(A12,ผู้เช่า!$A:$N,6,0),0) | E12: 1253 | F12: 1786 | G12: =IF(F12="","",F12-E12) | H12: =IF(G12="","",G12*IFERROR(VLOOKUP(A12,ผู้เช่า!$A:$N,9,0),0)) | I12: 502 | J12: 518 | K12: =IF(J12="","",J12-I12) | L12: =IF(K12="","",MAX(K12*IFERROR(VLOOKUP(A12,ผู้เช่า!$A:$N,10,0),0),IFERROR(VLOOKUP(A12,ผู้เช่า!$A:$N,14,0),0))) | M12: =IFERROR(VLOOKUP(A12,ผู้เช่า!$A:$N,7,0),0) | N12: =IFERROR(VLOOKUP(A12,ผู้เช่า!$A:$N,8,0),0) | O12: 0 | P12: =SUM(C12,D12,H12,L12,M12,N12,O12)
A13: 209 | B13: =IFERROR(VLOOKUP(A13,ผู้เช่า!$A:$N,2,0),"") | C13: =IFERROR(VLOOKUP(A13,ผู้เช่า!$A:$N,5,0),0) | D13: =IFERROR(VLOOKUP(A13,ผู้เช่า!$A:$N,6,0),0) | E13: 50 | F13: 233 | G13: =IF(F13="","",F13-E13) | H13: =IF(G13="","",G13*IFERROR(VLOOKUP(A13,ผู้เช่า!$A:$N,9,0),0)) | I13: 533 | J13: 538 | K13: =IF(J13="","",J13-I13) | L13: =IF(K13="","",MAX(K13*IFERROR(VLOOKUP(A13,ผู้เช่า!$A:$N,10,0),0),IFERROR(VLOOKUP(A13,ผู้เช่า!$A:$N,14,0),0))) | M13: =IFERROR(VLOOKUP(A13,ผู้เช่า!$A:$N,7,0),0) | N13: =IFERROR(VLOOKUP(A13,ผู้เช่า!$A:$N,8,0),0) | O13: 0 | P13: =SUM(C13,D13,H13,L13,M13,N13,O13)
A14: 210 | B14: =IFERROR(VLOOKUP(A14,ผู้เช่า!$A:$N,2,0),"") | C14: =IFERROR(VLOOKUP(A14,ผู้เช่า!$A:$N,5,0),0) | D14: =IFERROR(VLOOKUP(A14,ผู้เช่า!$A:$N,6,0),0) | E14: 9210 | F14: 9403 | G14: =IF(F14="","",F14-E14) | H14: =IF(G14="","",G14*IFERROR(VLOOKUP(A14,ผู้เช่า!$A:$N,9,0),0)) | I14: 597 | J14: 602 | K14: =IF(J14="","",J14-I14) | L14: =IF(K14="","",MAX(K14*IFERROR(VLOOKUP(A14,ผู้เช่า!$A:$N,10,0),0),IFERROR(VLOOKUP(A14,ผู้เช่า!$A:$N,14,0),0))) | M14: =IFERROR(VLOOKUP(A14,ผู้เช่า!$A:$N,7,0),0) | N14: =IFERROR(VLOOKUP(A14,ผู้เช่า!$A:$N,8,0),0) | O14: 0 | P14: =SUM(C14,D14,H14,L14,M14,N14,O14)
A15: 211 | B15: =IFERROR(VLOOKUP(A15,ผู้เช่า!$A:$N,2,0),"") | C15: =IFERROR(VLOOKUP(A15,ผู้เช่า!$A:$N,5,0),0) | D15: =IFERROR(VLOOKUP(A15,ผู้เช่า!$A:$N,6,0),0) | E15: 5982 | F15: 6195 | G15: =IF(F15="","",F15-E15) | H15: =IF(G15="","",G15*IFERROR(VLOOKUP(A15,ผู้เช่า!$A:$N,9,0),0)) | I15: 210 | J15: 213 | K15: =IF(J15="","",J15-I15) | L15: =IF(K15="","",MAX(K15*IFERROR(VLOOKUP(A15,ผู้เช่า!$A:$N,10,0),0),IFERROR(VLOOKUP(A15,ผู้เช่า!$A:$N,14,0),0))) | M15: =IFERROR(VLOOKUP(A15,ผู้เช่า!$A:$N,7,0),0) | N15: =IFERROR(VLOOKUP(A15,ผู้เช่า!$A:$N,8,0),0) | O15: 0 | P15: =SUM(C15,D15,H15,L15,M15,N15,O15)
A16: 212 | B16: =IFERROR(VLOOKUP(A16,ผู้เช่า!$A:$N,2,0),"") | C16: =IFERROR(VLOOKUP(A16,ผู้เช่า!$A:$N,5,0),0) | D16: =IFERROR(VLOOKUP(A16,ผู้เช่า!$A:$N,6,0),0) | E16: 2126 | F16: 2362 | G16: =IF(F16="","",F16-E16) | H16: =IF(G16="","",G16*IFERROR(VLOOKUP(A16,ผู้เช่า!$A:$N,9,0),0)) | I16: 561 | J16: 563 | K16: =IF(J16="","",J16-I16) | L16: =IF(K16="","",MAX(K16*IFERROR(VLOOKUP(A16,ผู้เช่า!$A:$N,10,0),0),IFERROR(VLOOKUP(A16,ผู้เช่า!$A:$N,14,0),0))) | M16: =IFERROR(VLOOKUP(A16,ผู้เช่า!$A:$N,7,0),0) | N16: =IFERROR(VLOOKUP(A16,ผู้เช่า!$A:$N,8,0),0) | O16: 0 | P16: =SUM(C16,D16,H16,L16,M16,N16,O16)
A17: 213 | B17: =IFERROR(VLOOKUP(A17,ผู้เช่า!$A:$N,2,0),"") | C17: =IFERROR(VLOOKUP(A17,ผู้เช่า!$A:$N,5,0),0) | D17: =IFERROR(VLOOKUP(A17,ผู้เช่า!$A:$N,6,0),0) | E17: 9704 | F17: 9752 | G17: =IF(F17="","",F17-E17) | H17: =IF(G17="","",G17*IFERROR(VLOOKUP(A17,ผู้เช่า!$A:$N,9,0),0)) | I17: 345 | J17: 349 | K17: =IF(J17="","",J17-I17) | L17: =IF(K17="","",MAX(K17*IFERROR(VLOOKUP(A17,ผู้เช่า!$A:$N,10,0),0),IFERROR(VLOOKUP(A17,ผู้เช่า!$A:$N,14,0),0))) | M17: =IFERROR(VLOOKUP(A17,ผู้เช่า!$A:$N,7,0),0) | N17: =IFERROR(VLOOKUP(A17,ผู้เช่า!$A:$N,8,0),0) | O17: 0 | P17: =SUM(C17,D17,H17,L17,M17,N17,O17)
A18: 214 | B18: =IFERROR(VLOOKUP(A18,ผู้เช่า!$A:$N,2,0),"") | C18: =IFERROR(VLOOKUP(A18,ผู้เช่า!$A:$N,5,0),0) | D18: =IFERROR(VLOOKUP(A18,ผู้เช่า!$A:$N,6,0),0) | E18: 7449 | F18: 7656 | G18: =IF(F18="","",F18-E18) | H18: =IF(G18="","",G18*IFERROR(VLOOKUP(A18,ผู้เช่า!$A:$N,9,0),0)) | I18: 269 | J18: 274 | K18: =IF(J18="","",J18-I18) | L18: =IF(K18="","",MAX(K18*IFERROR(VLOOKUP(A18,ผู้เช่า!$A:$N,10,0),0),IFERROR(VLOOKUP(A18,ผู้เช่า!$A:$N,14,0),0))) | M18: =IFERROR(VLOOKUP(A18,ผู้เช่า!$A:$N,7,0),0) | N18: =IFERROR(VLOOKUP(A18,ผู้เช่า!$A:$N,8,0),0) | O18: 100 | P18: =SUM(C18,D18,H18,L18,M18,N18,O18)
A19: 215 | B19: =IFERROR(VLOOKUP(A19,ผู้เช่า!$A:$N,2,0),"") | C19: =IFERROR(VLOOKUP(A19,ผู้เช่า!$A:$N,5,0),0) | D19: =IFERROR(VLOOKUP(A19,ผู้เช่า!$A:$N,6,0),0) | E19: 7458 | F19: 7687 | G19: =IF(F19="","",F19-E19) | H19: =IF(G19="","",G19*IFERROR(VLOOKUP(A19,ผู้เช่า!$A:$N,9,0),0)) | I19: 326 | J19: 327 | K19: =IF(J19="","",J19-I19) | L19: =IF(K19="","",MAX(K19*IFERROR(VLOOKUP(A19,ผู้เช่า!$A:$N,10,0),0),IFERROR(VLOOKUP(A19,ผู้เช่า!$A:$N,14,0),0))) | M19: =IFERROR(VLOOKUP(A19,ผู้เช่า!$A:$N,7,0),0) | N19: =IFERROR(VLOOKUP(A19,ผู้เช่า!$A:$N,8,0),0) | O19: 0 | P19: =SUM(C19,D19,H19,L19,M19,N19,O19)
A20: 216 | B20: =IFERROR(VLOOKUP(A20,ผู้เช่า!$A:$N,2,0),"") | C20: =IFERROR(VLOOKUP(A20,ผู้เช่า!$A:$N,5,0),0) | D20: =IFERROR(VLOOKUP(A20,ผู้เช่า!$A:$N,6,0),0) | E20: 1855 | F20: 1887 | G20: =IF(F20="","",F20-E20) | H20: =IF(G20="","",G20*IFERROR(VLOOKUP(A20,ผู้เช่า!$A:$N,9,0),0)) | I20: 487 | J20: 492 | K20: =IF(J20="","",J20-I20) | L20: =IF(K20="","",MAX(K20*IFERROR(VLOOKUP(A20,ผู้เช่า!$A:$N,10,0),0),IFERROR(VLOOKUP(A20,ผู้เช่า!$A:$N,14,0),0))) | M20: =IFERROR(VLOOKUP(A20,ผู้เช่า!$A:$N,7,0),0) | N20: =IFERROR(VLOOKUP(A20,ผู้เช่า!$A:$N,8,0),0) | O20: 0 | P20: =SUM(C20,D20,H20,L20,M20,N20,O20)
A21: 217 | B21: =IFERROR(VLOOKUP(A21,ผู้เช่า!$A:$N,2,0),"") | C21: =IFERROR(VLOOKUP(A21,ผู้เช่า!$A:$N,5,0),0) | D21: =IFERROR(VLOOKUP(A21,ผู้เช่า!$A:$N,6,0),0) | E21: 1855 | F21: 1940 | G21: =IF(F21="","",F21-E21) | H21: =IF(G21="","",G21*IFERROR(VLOOKUP(A21,ผู้เช่า!$A:$N,9,0),0)) | I21: 364 | J21: 365 | K21: =IF(J21="","",J21-I21) | L21: =IF(K21="","",MAX(K21*IFERROR(VLOOKUP(A21,ผู้เช่า!$A:$N,10,0),0),IFERROR(VLOOKUP(A21,ผู้เช่า!$A:$N,14,0),0))) | M21: =IFERROR(VLOOKUP(A21,ผู้เช่า!$A:$N,7,0),0) | N21: =IFERROR(VLOOKUP(A21,ผู้เช่า!$A:$N,8,0),0) | O21: 0 | P21: =SUM(C21,D21,H21,L21,M21,N21,O21)
... A34: 312 | B34: =IFERROR(VLOOKUP(A34,ผู้เช่า!$A:$N,2,0),"") | C34: =IFERROR(VLOOKUP(A34,ผู้เช่า!$A:$N,5,0),0) | D34: =IFERROR(VLOOKUP(A34,ผู้เช่า!$A:$N,6,0),0) | E34: 2617 | F34: 2708 | G34: =IF(F34="","",F34-E34) | H34: =IF(G34="","",G34*IFERROR(VLOOKUP(A34,ผู้เช่า!$A:$N,9,0),0)) | I34: 260 | J34: 261 | K34: =IF(J34="","",J34-I34) | L34: =IF(K34="","",MAX(K34*IFERROR(VLOOKUP(A34,ผู้เช่า!$A:$N,10,0),0),IFERROR(VLOOKUP(A34,ผู้เช่า!$A:$N,14,0),0))) | M34: =IFERROR(VLOOKUP(A34,ผู้เช่า!$A:$N,7,0),0) | N34: =IFERROR(VLOOKUP(A34,ผู้เช่า!$A:$N,8,0),0) | O34: 0 | P34: =SUM(C34,D34,H34,L34,M34,N34,O34)
A35: 313 | B35: =IFERROR(VLOOKUP(A35,ผู้เช่า!$A:$N,2,0),"") | C35: =IFERROR(VLOOKUP(A35,ผู้เช่า!$A:$N,5,0),0) | D35: =IFERROR(VLOOKUP(A35,ผู้เช่า!$A:$N,6,0),0) | G35: =IF(F35="","",F35-E35) | H35: =IF(G35="","",G35*IFERROR(VLOOKUP(A35,ผู้เช่า!$A:$N,9,0),0)) | K35: =IF(J35="","",J35-I35) | L35: =IF(K35="","",MAX(K35*IFERROR(VLOOKUP(A35,ผู้เช่า!$A:$N,10,0),0),IFERROR(VLOOKUP(A35,ผู้เช่า!$A:$N,14,0),0))) | M35: =IFERROR(VLOOKUP(A35,ผู้เช่า!$A:$N,7,0),0) | N35: =IFERROR(VLOOKUP(A35,ผู้เช่า!$A:$N,8,0),0) | O35: 0 | P35: =SUM(C35,D35,H35,L35,M35,N35,O35)
A36: 314 | B36: =IFERROR(VLOOKUP(A36,ผู้เช่า!$A:$N,2,0),"") | C36: =IFERROR(VLOOKUP(A36,ผู้เช่า!$A:$N,5,0),0) | D36: =IFERROR(VLOOKUP(A36,ผู้เช่า!$A:$N,6,0),0) | E36: 7740 | F36: 7783 | G36: =IF(F36="","",F36-E36) | H36: =IF(G36="","",G36*IFERROR(VLOOKUP(A36,ผู้เช่า!$A:$N,9,0),0)) | I36: 312 | J36: 317 | K36: =IF(J36="","",J36-I36) | L36: =IF(K36="","",MAX(K36*IFERROR(VLOOKUP(A36,ผู้เช่า!$A:$N,10,0),0),IFERROR(VLOOKUP(A36,ผู้เช่า!$A:$N,14,0),0))) | M36: =IFERROR(VLOOKUP(A36,ผู้เช่า!$A:$N,7,0),0) | N36: =IFERROR(VLOOKUP(A36,ผู้เช่า!$A:$N,8,0),0) | O36: 250 | P36: =SUM(C36,D36,H36,L36,M36,N36,O36)
A37: 315 | B37: =IFERROR(VLOOKUP(A37,ผู้เช่า!$A:$N,2,0),"") | C37: =IFERROR(VLOOKUP(A37,ผู้เช่า!$A:$N,5,0),0) | D37: =IFERROR(VLOOKUP(A37,ผู้เช่า!$A:$N,6,0),0) | E37: 6422 | F37: 6637 | G37: =IF(F37="","",F37-E37) | H37: =IF(G37="","",G37*IFERROR(VLOOKUP(A37,ผู้เช่า!$A:$N,9,0),0)) | I37: 226 | J37: 231 | K37: =IF(J37="","",J37-I37) | L37: =IF(K37="","",MAX(K37*IFERROR(VLOOKUP(A37,ผู้เช่า!$A:$N,10,0),0),IFERROR(VLOOKUP(A37,ผู้เช่า!$A:$N,14,0),0))) | M37: =IFERROR(VLOOKUP(A37,ผู้เช่า!$A:$N,7,0),0) | N37: =IFERROR(VLOOKUP(A37,ผู้เช่า!$A:$N,8,0),0) | O37: 150 | P37: =SUM(C37,D37,H37,L37,M37,N37,O37)
A38: 316 | B38: =IFERROR(VLOOKUP(A38,ผู้เช่า!$A:$N,2,0),"") | C38: =IFERROR(VLOOKUP(A38,ผู้เช่า!$A:$N,5,0),0) | D38: =IFERROR(VLOOKUP(A38,ผู้เช่า!$A:$N,6,0),0) | E38: 9923 | F38: 9984 | G38: =IF(F38="","",F38-E38) | H38: =IF(G38="","",G38*IFERROR(VLOOKUP(A38,ผู้เช่า!$A:$N,9,0),0)) | I38: 334 | J38: 339 | K38: =IF(J38="","",J38-I38) | L38: =IF(K38="","",MAX(K38*IFERROR(VLOOKUP(A38,ผู้เช่า!$A:$N,10,0),0),IFERROR(VLOOKUP(A38,ผู้เช่า!$A:$N,14,0),0))) | M38: =IFERROR(VLOOKUP(A38,ผู้เช่า!$A:$N,7,0),0) | N38: =IFERROR(VLOOKUP(A38,ผู้เช่า!$A:$N,8,0),0) | O38: 0 | P38: =SUM(C38,D38,H38,L38,M38,N38,O38)
A39: 317 | B39: =IFERROR(VLOOKUP(A39,ผู้เช่า!$A:$N,2,0),"") | C39: =IFERROR(VLOOKUP(A39,ผู้เช่า!$A:$N,5,0),0) | D39: =IFERROR(VLOOKUP(A39,ผู้เช่า!$A:$N,6,0),0) | G39: =IF(F39="","",F39-E39) | H39: =IF(G39="","",G39*IFERROR(VLOOKUP(A39,ผู้เช่า!$A:$N,9,0),0)) | K39: =IF(J39="","",J39-I39) | L39: =IF(K39="","",MAX(K39*IFERROR(VLOOKUP(A39,ผู้เช่า!$A:$N,10,0),0),IFERROR(VLOOKUP(A39,ผู้เช่า!$A:$N,14,0),0))) | M39: =IFERROR(VLOOKUP(A39,ผู้เช่า!$A:$N,7,0),0) | N39: =IFERROR(VLOOKUP(A39,ผู้เช่า!$A:$N,8,0),0) | O39: 0 | P39: =SUM(C39,D39,H39,L39,M39,N39,O39)
A40: 318 | B40: =IFERROR(VLOOKUP(A40,ผู้เช่า!$A:$N,2,0),"") | C40: =IFERROR(VLOOKUP(A40,ผู้เช่า!$A:$N,5,0),0) | D40: =IFERROR(VLOOKUP(A40,ผู้เช่า!$A:$N,6,0),0) | E40: 1656 | F40: 1732 | G40: =IF(F40="","",F40-E40) | H40: =IF(G40="","",G40*IFERROR(VLOOKUP(A40,ผู้เช่า!$A:$N,9,0),0)) | I40: 220 | J40: 223 | K40: =IF(J40="","",J40-I40) | L40: =IF(K40="","",MAX(K40*IFERROR(VLOOKUP(A40,ผู้เช่า!$A:$N,10,0),0),IFERROR(VLOOKUP(A40,ผู้เช่า!$A:$N,14,0),0))) | M40: =IFERROR(VLOOKUP(A40,ผู้เช่า!$A:$N,7,0),0) | N40: =IFERROR(VLOOKUP(A40,ผู้เช่า!$A:$N,8,0),0) | O40: 0 | P40: =SUM(C40,D40,H40,L40,M40,N40,O40)
A41: 401 | B41: =IFERROR(VLOOKUP(A41,ผู้เช่า!$A:$N,2,0),"") | C41: =IFERROR(VLOOKUP(A41,ผู้เช่า!$A:$N,5,0),0) | D41: =IFERROR(VLOOKUP(A41,ผู้เช่า!$A:$N,6,0),0) | E41: 5901 | F41: 6153 | G41: =IF(F41="","",F41-E41) | H41: =IF(G41="","",G41*IFERROR(VLOOKUP(A41,ผู้เช่า!$A:$N,9,0),0)) | I41: 377 | J41: 378 | K41: =IF(J41="","",J41-I41) | L41: =IF(K41="","",MAX(K41*IFERROR(VLOOKUP(A41,ผู้เช่า!$A:$N,10,0),0),IFERROR(VLOOKUP(A41,ผู้เช่า!$A:$N,14,0),0))) | M41: =IFERROR(VLOOKUP(A41,ผู้เช่า!$A:$N,7,0),0) | N41: =IFERROR(VLOOKUP(A41,ผู้เช่า!$A:$N,8,0),0) | O41: 250 | P41: =SUM(C41,D41,H41,L41,M41,N41,O41)
A42: 402 | B42: =IFERROR(VLOOKUP(A42,ผู้เช่า!$A:$N,2,0),"") | C42: =IFERROR(VLOOKUP(A42,ผู้เช่า!$A:$N,5,0),0) | D42: =IFERROR(VLOOKUP(A42,ผู้เช่า!$A:$N,6,0),0) | E42: 7864 | F42: 8226 | G42: =IF(F42="","",F42-E42) | H42: =IF(G42="","",G42*IFERROR(VLOOKUP(A42,ผู้เช่า!$A:$N,9,0),0)) | I42: 432 | J42: 441 | K42: =IF(J42="","",J42-I42) | L42: =IF(K42="","",MAX(K42*IFERROR(VLOOKUP(A42,ผู้เช่า!$A:$N,10,0),0),IFERROR(VLOOKUP(A42,ผู้เช่า!$A:$N,14,0),0))) | M42: =IFERROR(VLOOKUP(A42,ผู้เช่า!$A:$N,7,0),0) | N42: =IFERROR(VLOOKUP(A42,ผู้เช่า!$A:$N,8,0),0) | O42: 0 | P42: =SUM(C42,D42,H42,L42,M42,N42,O42)
A43: 403 | B43: =IFERROR(VLOOKUP(A43,ผู้เช่า!$A:$N,2,0),"") | C43: =IFERROR(VLOOKUP(A43,ผู้เช่า!$A:$N,5,0),0) | D43: =IFERROR(VLOOKUP(A43,ผู้เช่า!$A:$N,6,0),0) | E43: 1250 | F43: 1262 | G43: =IF(F43="","",F43-E43) | H43: =IF(G43="","",G43*IFERROR(VLOOKUP(A43,ผู้เช่า!$A:$N,9,0),0)) | I43: 349 | J43: 356 | K43: =IF(J43="","",J43-I43) | L43: =IF(K43="","",MAX(K43*IFERROR(VLOOKUP(A43,ผู้เช่า!$A:$N,10,0),0),IFERROR(VLOOKUP(A43,ผู้เช่า!$A:$N,14,0),0))) | M43: =IFERROR(VLOOKUP(A43,ผู้เช่า!$A:$N,7,0),0) | N43: =IFERROR(VLOOKUP(A43,ผู้เช่า!$A:$N,8,0),0) | O43: 0 | P43: =SUM(C43,D43,H43,L43,M43,N43,O43)
A44: 404 | B44: =IFERROR(VLOOKUP(A44,ผู้เช่า!$A:$N,2,0),"") | C44: =IFERROR(VLOOKUP(A44,ผู้เช่า!$A:$N,5,0),0) | D44: =IFERROR(VLOOKUP(A44,ผู้เช่า!$A:$N,6,0),0) | E44: 8938 | F44: 8944 | G44: =IF(F44="","",F44-E44) | H44: =IF(G44="","",G44*IFERROR(VLOOKUP(A44,ผู้เช่า!$A:$N,9,0),0)) | I44: 315 | J44: 316 | K44: =IF(J44="","",J44-I44) | L44: =IF(K44="","",MAX(K44*IFERROR(VLOOKUP(A44,ผู้เช่า!$A:$N,10,0),0),IFERROR(VLOOKUP(A44,ผู้เช่า!$A:$N,14,0),0))) | M44: =IFERROR(VLOOKUP(A44,ผู้เช่า!$A:$N,7,0),0) | N44: =IFERROR(VLOOKUP(A44,ผู้เช่า!$A:$N,8,0),0) | O44: 0 | P44: =SUM(C44,D44,H44,L44,M44,N44,O44)
A45: 405 | B45: =IFERROR(VLOOKUP(A45,ผู้เช่า!$A:$N,2,0),"") | C45: =IFERROR(VLOOKUP(A45,ผู้เช่า!$A:$N,5,0),0) | D45: =IFERROR(VLOOKUP(A45,ผู้เช่า!$A:$N,6,0),0) | E45: 12090 | F45: 12262 | G45: =IF(F45="","",F45-E45) | H45: =IF(G45="","",G45*IFERROR(VLOOKUP(A45,ผู้เช่า!$A:$N,9,0),0)) | I45: 320 | J45: 325 | K45: =IF(J45="","",J45-I45) | L45: =IF(K45="","",MAX(K45*IFERROR(VLOOKUP(A45,ผู้เช่า!$A:$N,10,0),0),IFERROR(VLOOKUP(A45,ผู้เช่า!$A:$N,14,0),0))) | M45: =IFERROR(VLOOKUP(A45,ผู้เช่า!$A:$N,7,0),0) | N45: =IFERROR(VLOOKUP(A45,ผู้เช่า!$A:$N,8,0),0) | O45: 100 | P45: =SUM(C45,D45,H45,L45,M45,N45,O45)
A46: 406 | B46: =IFERROR(VLOOKUP(A46,ผู้เช่า!$A:$N,2,0),"") | C46: =IFERROR(VLOOKUP(A46,ผู้เช่า!$A:$N,5,0),0) | D46: =IFERROR(VLOOKUP(A46,ผู้เช่า!$A:$N,6,0),0) | E46: 4992 | F46: 5157 | G46: =IF(F46="","",F46-E46) | H46: =IF(G46="","",G46*IFERROR(VLOOKUP(A46,ผู้เช่า!$A:$N,9,0),0)) | I46: 467 | J46: 475 | K46: =IF(J46="","",J46-I46) | L46: =IF(K46="","",MAX(K46*IFERROR(VLOOKUP(A46,ผู้เช่า!$A:$N,10,0),0),IFERROR(VLOOKUP(A46,ผู้เช่า!$A:$N,14,0),0))) | M46: =IFERROR(VLOOKUP(A46,ผู้เช่า!$A:$N,7,0),0) | N46: =IFERROR(VLOOKUP(A46,ผู้เช่า!$A:$N,8,0),0) | O46: 300 | P46: =SUM(C46,D46,H46,L46,M46,N46,O46)
A47: 407 | B47: =IFERROR(VLOOKUP(A47,ผู้เช่า!$A:$N,2,0),"") | C47: =IFERROR(VLOOKUP(A47,ผู้เช่า!$A:$N,5,0),0) | D47: =IFERROR(VLOOKUP(A47,ผู้เช่า!$A:$N,6,0),0) | E47: 2083 | F47: 2175 | G47: =IF(F47="","",F47-E47) | H47: =IF(G47="","",G47*IFERROR(VLOOKUP(A47,ผู้เช่า!$A:$N,9,0),0)) | I47: 331 | J47: 336 | K47: =IF(J47="","",J47-I47) | L47: =IF(K47="","",MAX(K47*IFERROR(VLOOKUP(A47,ผู้เช่า!$A:$N,10,0),0),IFERROR(VLOOKUP(A47,ผู้เช่า!$A:$N,14,0),0))) | M47: =IFERROR(VLOOKUP(A47,ผู้เช่า!$A:$N,7,0),0) | N47: =IFERROR(VLOOKUP(A47,ผู้เช่า!$A:$N,8,0),0) | O47: 250 | P47: =SUM(C47,D47,H47,L47,M47,N47,O47)
A48: 408 | B48: =IFERROR(VLOOKUP(A48,ผู้เช่า!$A:$N,2,0),"") | C48: =IFERROR(VLOOKUP(A48,ผู้เช่า!$A:$N,5,0),0) | D48: =IFERROR(VLOOKUP(A48,ผู้เช่า!$A:$N,6,0),0) | E48: 8762 | F48: 8820 | G48: =IF(F48="","",F48-E48) | H48: =IF(G48="","",G48*IFERROR(VLOOKUP(A48,ผู้เช่า!$A:$N,9,0),0)) | I48: 314 | J48: 319 | K48: =IF(J48="","",J48-I48) | L48: =IF(K48="","",MAX(K48*IFERROR(VLOOKUP(A48,ผู้เช่า!$A:$N,10,0),0),IFERROR(VLOOKUP(A48,ผู้เช่า!$A:$N,14,0),0))) | M48: =IFERROR(VLOOKUP(A48,ผู้เช่า!$A:$N,7,0),0) | N48: =IFERROR(VLOOKUP(A48,ผู้เช่า!$A:$N,8,0),0) | O48: 250 | P48: =SUM(C48,D48,H48,L48,M48,N48,O48)
A49: 409 | B49: =IFERROR(VLOOKUP(A49,ผู้เช่า!$A:$N,2,0),"") | C49: =IFERROR(VLOOKUP(A49,ผู้เช่า!$A:$N,5,0),0) | D49: =IFERROR(VLOOKUP(A49,ผู้เช่า!$A:$N,6,0),0) | E49: 1887 | F49: 2151 | G49: =IF(F49="","",F49-E49) | H49: =IF(G49="","",G49*IFERROR(VLOOKUP(A49,ผู้เช่า!$A:$N,9,0),0)) | I49: 401 | J49: 407 | K49: =IF(J49="","",J49-I49) | L49: =IF(K49="","",MAX(K49*IFERROR(VLOOKUP(A49,ผู้เช่า!$A:$N,10,0),0),IFERROR(VLOOKUP(A49,ผู้เช่า!$A:$N,14,0),0))) | M49: =IFERROR(VLOOKUP(A49,ผู้เช่า!$A:$N,7,0),0) | N49: =IFERROR(VLOOKUP(A49,ผู้เช่า!$A:$N,8,0),0) | O49: 300 | P49: =SUM(C49,D49,H49,L49,M49,N49,O49)
A50: 410 | B50: =IFERROR(VLOOKUP(A50,ผู้เช่า!$A:$N,2,0),"") | C50: =IFERROR(VLOOKUP(A50,ผู้เช่า!$A:$N,5,0),0) | D50: =IFERROR(VLOOKUP(A50,ผู้เช่า!$A:$N,6,0),0) | E50: 8781 | F50: 8948 | G50: =IF(F50="","",F50-E50) | H50: =IF(G50="","",G50*IFERROR(VLOOKUP(A50,ผู้เช่า!$A:$N,9,0),0)) | I50: 502 | J50: 515 | K50: =IF(J50="","",J50-I50) | L50: =IF(K50="","",MAX(K50*IFERROR(VLOOKUP(A50,ผู้เช่า!$A:$N,10,0),0),IFERROR(VLOOKUP(A50,ผู้เช่า!$A:$N,14,0),0))) | M50: =IFERROR(VLOOKUP(A50,ผู้เช่า!$A:$N,7,0),0) | N50: =IFERROR(VLOOKUP(A50,ผู้เช่า!$A:$N,8,0),0) | O50: 0 | P50: =SUM(C50,D50,H50,L50,M50,N50,O50)
A51: 411 | B51: =IFERROR(VLOOKUP(A51,ผู้เช่า!$A:$N,2,0),"") | C51: =IFERROR(VLOOKUP(A51,ผู้เช่า!$A:$N,5,0),0) | D51: =IFERROR(VLOOKUP(A51,ผู้เช่า!$A:$N,6,0),0) | E51: 2107 | F51: 2121 | G51: =IF(F51="","",F51-E51) | H51: =IF(G51="","",G51*IFERROR(VLOOKUP(A51,ผู้เช่า!$A:$N,9,0),0)) | I51: 296 | J51: 308 | K51: =IF(J51="","",J51-I51) | L51: =IF(K51="","",MAX(K51*IFERROR(VLOOKUP(A51,ผู้เช่า!$A:$N,10,0),0),IFERROR(VLOOKUP(A51,ผู้เช่า!$A:$N,14,0),0))) | M51: =IFERROR(VLOOKUP(A51,ผู้เช่า!$A:$N,7,0),0) | N51: =IFERROR(VLOOKUP(A51,ผู้เช่า!$A:$N,8,0),0) | O51: 0 | P51: =SUM(C51,D51,H51,L51,M51,N51,O51)
... A68: 510 | B68: =IFERROR(VLOOKUP(A68,ผู้เช่า!$A:$N,2,0),"") | C68: =IFERROR(VLOOKUP(A68,ผู้เช่า!$A:$N,5,0),0) | D68: =IFERROR(VLOOKUP(A68,ผู้เช่า!$A:$N,6,0),0) | E68: 7641 | F68: 7799 | G68: =IF(F68="","",F68-E68) | H68: =IF(G68="","",G68*IFERROR(VLOOKUP(A68,ผู้เช่า!$A:$N,9,0),0)) | I68: 304 | J68: 309 | K68: =IF(J68="","",J68-I68) | L68: =IF(K68="","",MAX(K68*IFERROR(VLOOKUP(A68,ผู้เช่า!$A:$N,10,0),0),IFERROR(VLOOKUP(A68,ผู้เช่า!$A:$N,14,0),0))) | M68: =IFERROR(VLOOKUP(A68,ผู้เช่า!$A:$N,7,0),0) | N68: =IFERROR(VLOOKUP(A68,ผู้เช่า!$A:$N,8,0),0) | O68: 0 | P68: =SUM(C68,D68,H68,L68,M68,N68,O68)
A69: 511 | B69: =IFERROR(VLOOKUP(A69,ผู้เช่า!$A:$N,2,0),"") | C69: =IFERROR(VLOOKUP(A69,ผู้เช่า!$A:$N,5,0),0) | D69: =IFERROR(VLOOKUP(A69,ผู้เช่า!$A:$N,6,0),0) | E69: 6864 | F69: 6982 | G69: =IF(F69="","",F69-E69) | H69: =IF(G69="","",G69*IFERROR(VLOOKUP(A69,ผู้เช่า!$A:$N,9,0),0)) | K69: =IF(J69="","",J69-I69) | L69: =IF(K69="","",MAX(K69*IFERROR(VLOOKUP(A69,ผู้เช่า!$A:$N,10,0),0),IFERROR(VLOOKUP(A69,ผู้เช่า!$A:$N,14,0),0))) | M69: =IFERROR(VLOOKUP(A69,ผู้เช่า!$A:$N,7,0),0) | N69: =IFERROR(VLOOKUP(A69,ผู้เช่า!$A:$N,8,0),0) | O69: 0 | P69: =SUM(C69,D69,H69,L69,M69,N69,O69)
...

Sheet ใบแจ้งหนี้
A1: ใบแจ้งหนี้ | J1: เลือกห้อง:
A2: อพาร์ทเม้นท์ มั่งมีทวีสุข | J2: 201
A3: 558/1 ถนนท่าดินแดง 16 แขวงคลองสาน เขตคลองสาน กรุงเทพฯ 10600 | J3: ← เลือกห้องที่นี่
A5: ชื่อลูกค้า : | B5: =IFERROR(VLOOKUP($J$2,ผู้เช่า!$A:$N,2,0),"") | F5: ห้อง : | G5: =$J$2
A6: ที่อยู่ : | B6: =IFERROR(VLOOKUP($J$2,ผู้เช่า!$A:$N,3,0),"") | F6: วันที่ : | G6: =TEXT(TODAY(),"d/m/yyyy")
F7: เดือนค่าเช่า : | G7: ='บันทึกค่าน้ำไฟ'!$D$1
F8: เดือนน้ำ-ไฟ : | G8: ='บันทึกค่าน้ำไฟ'!$D$2
A10: ลำดับ | B10: รายการ | D10: จำนวน | E10: หน่วย | F10: ราคา/หน่วย | G10: จำนวนเงิน
A11: 1 | B11: ค่าเช่าห้อง | D11: 1 | E11: ห้อง | F11: =IFERROR(VLOOKUP($J$2,'บันทึกค่าน้ำไฟ'!$A:$P,3,0),0) | G11: =IFERROR(VLOOKUP($J$2,'บันทึกค่าน้ำไฟ'!$A:$P,3,0),0)
A12: 2 | B12: ค่าเช่าเฟอร์นิเจอร์ | D12: 1 | E12: ชุด | F12: =IFERROR(VLOOKUP($J$2,'บันทึกค่าน้ำไฟ'!$A:$P,4,0),0) | G12: =IFERROR(VLOOKUP($J$2,'บันทึกค่าน้ำไฟ'!$A:$P,4,0),0)
A13: 3 | B13: ="ค่าไฟฟ้า (เลขเก่า "&IFERROR(VLOOKUP($J$2,'บันทึกค่าน้ำไฟ'!$A:$P,5,0),"")&" ถึง "&IFERROR(VLOOKUP($J$2,'บันทึกค่าน้ำไฟ'!$A:$P,6,0),"")&")" | D13: =IFERROR(VLOOKUP($J$2,'บันทึกค่าน้ำไฟ'!$A:$P,7,0),0) | E13: ยูนิต | F13: =IFERROR(VLOOKUP($J$2,ผู้เช่า!$A:$N,9,0),0) | G13: =IFERROR(VLOOKUP($J$2,'บันทึกค่าน้ำไฟ'!$A:$P,8,0),0)
A14: 4 | B14: ="ค่าน้ำประปา (เลขเก่า "&IFERROR(VLOOKUP($J$2,'บันทึกค่าน้ำไฟ'!$A:$P,9,0),"")&" ถึง "&IFERROR(VLOOKUP($J$2,'บันทึกค่าน้ำไฟ'!$A:$P,10,0),"")&")" | D14: =IFERROR(VLOOKUP($J$2,'บันทึกค่าน้ำไฟ'!$A:$P,11,0),0) | E14: ยูนิต | F14: =IFERROR(VLOOKUP($J$2,ผู้เช่า!$A:$N,10,0),0) | G14: =IFERROR(VLOOKUP($J$2,'บันทึกค่าน้ำไฟ'!$A:$P,12,0),0)
A15: 5 | B15: ค่าส่วนกลาง | D15: 1 | E15: เดือน | F15: =IFERROR(VLOOKUP($J$2,'บันทึกค่าน้ำไฟ'!$A:$P,13,0),0) | G15: =IFERROR(VLOOKUP($J$2,'บันทึกค่าน้ำไฟ'!$A:$P,13,0),0)
A16: 6 | B16: ค่าขยะ | D16: 1 | E16: เดือน | F16: =IFERROR(VLOOKUP($J$2,'บันทึกค่าน้ำไฟ'!$A:$P,14,0),0) | G16: =IFERROR(VLOOKUP($J$2,'บันทึกค่าน้ำไฟ'!$A:$P,14,0),0)
A17: 7 | B17: อื่นๆ | G17: =IFERROR(VLOOKUP($J$2,'บันทึกค่าน้ำไฟ'!$A:$P,15,0),0)
A18: ="หมายเหตุ : ค่าเช่าห้องเดือน "&'บันทึกค่าน้ำไฟ'!$D$1&" / ค่าน้ำ-ค่าไฟเดือน "&'บันทึกค่าน้ำไฟ'!$D$2
F19: รวมทั้งสิ้น (บาท) | G19: =IFERROR(VLOOKUP($J$2,'บันทึกค่าน้ำไฟ'!$A:$P,16,0),0)
A20: ="(ตัวอักษร) "&IFERROR(BAHTTEXT(IFERROR(VLOOKUP($J$2,'บันทึกค่าน้ำไฟ'!$A:$P,16,0),0)),"")
A22: ชำระเงินผ่าน : ธนาคารเกียรตินาคินภัทร เลขที่บัญชี 20-0208389-2 นายชวนันท์ สุขพรชัยรัก
A23: กรุณาชำระภายในวันที่ 5 ของเดือนถัดไป (ชำระหลังวันที่ 5 คิดค่าธรรมเนียมล่าช้าวันละ 200 บาท)
A24: โอนแล้วกรุณาแจ้งผ่าน LINE ID : MT.Apartment (หากไม่แจ้ง ทางเราจะถือว่ายังไม่ได้รับเงินค่ะ)
F27: ผู้จัดทำ ...............................................

Sheet ผู้เช่า
A1: ห้อง | B1: ชื่อผู้เช่า | C1: ที่อยู่ | D1: เบอร์โทร | E1: ค่าเช่า/เดือน | F1: ค่าเฟอร์/เดือน | G1: ค่าส่วนกลาง | H1: ค่าขยะ | I1: เรทค่าไฟ/หน่วย | J1: เรทค่าน้ำ/หน่วย | K1: เลขที่สัญญา | L1: วันเข้าอยู่ | M1: สถานะ/หมายเหตุ | N1: ค่าน้ำขั้นต่ำ
A2: 201 | B2: นางสาวญาติกาญจน์ การไมตรี | C2: 463/14 หมู่ที่ 4 ต.ท้ายบ้าน อ.เมืองสมุทรปราการ จ.สมุทรปราการ | D2: 064-2461758 | E2: 5500 | F2: 0 | G2: 0 | H2: 0 | I2: 8 | J2: 20 | K2: 201/0001-2569 | L2: 2026-05-15 00:00:00 | M2: ย้ายเข้า 15 พ.ค.69 | N2: 100
A3: 202 | E3: 0 | F3: 0 | G3: 0 | H3: 0 | I3: 8 | J3: 20 | K3: 201/0001-2565 | N3: 100
A4: 203 | B4: นางสาวปัทมา กงกะเรียน | C4: 179 ม.1 ต.ผาสามยอด อ.เอราวัณ จ.เลย | D4: 080-754-4074 | E4: 4500 | F4: 0 | G4: 0 | H4: 0 | I4: 8 | J4: 20 | K4: 203/0004-2564 | L4: 2021-03-28 00:00:00 | N4: 100
A5: 204 | B5: นายธนัท ศรีทอง | C5: 389/152 ม.6 ต.แพรกษา อ.เมือง จ.สมุทรปราการ | D5: 089-4971424 | E5: 4500 | F5: 0 | G5: 0 | H5: 0 | I5: 8 | J5: 20 | K5: 204/0004-2565 | L5: 2022-10-01 00:00:00 | N5: 100
A6: 205 | E6: 0 | F6: 0 | G6: 0 | H6: 0 | I6: 8 | J6: 20 | K6: 205/0001-2569 | M6: ย้ายออก 1 พ.ค.69 | N6: 100
A7: 206 | B7: นางสาวรตนกร ปะนะพุตโต | C7: 2 ม.6 ต.ดงบัง อ.นาดูน จ.มหาสารคาม | D7: 094-9842789 | E7: 5500 | F7: 0 | G7: 0 | H7: 0 | I7: 8 | J7: 20 | K7: 206/0003-2568 | L7: 2025-03-01 00:00:00 | N7: 100
A8: 207 | B8: นายภาสกรณ์ ประทุมพล | C8: 191 ม.6 ต.เมือง อ.เมือง จ.ขอนแก่น | D8: 091-0612524 | E8: 4500 | F8: 0 | G8: 0 | H8: 0 | I8: 8 | J8: 20 | K8: 207/0005-2565 | L8: 2022-07-29 00:00:00 | N8: 100
A9: 208 | B9: shu jie | E9: 4900 | F9: 0 | G9: 0 | H9: 0 | I9: 8 | J9: 20 | K9: 208/0001-2568 | L9: 2025-12-07 00:00:00 | N9: 100
A10: 209 | B10: นางสาวพัชราภรณ์ ช่วยเกลี้ยง | C10: 30/4 ม.1 ต.บ้าหวี อ.หาดสำราญ จ.ตรัง | D10: 092-9162955 | E10: 4500 | F10: 0 | G10: 0 | H10: 0 | I10: 8 | J10: 20 | K10: 209/0005-2566 | L10: 2023-07-02 00:00:00 | N10: 100
A11: 210 | B11: นางสาวเมธาวี ศรีสุวรรณหงษ์ | C11: 41/1 หมู่ที่ 1 ต.เทพมงคล อ.บางซ้าย จ.พระนครศรีอยุธยา | D11: 095-5940915 | E11: 5500 | F11: 0 | G11: 0 | H11: 0 | I11: 8 | J11: 20 | K11: 210/0001-2568 | L11: 2025-11-16 00:00:00 | N11: 100
A12: 211 | B12: นายทวีรัฐ ทองแว่น | C12: 203 หมู่ที่ 2 ต.ธงชัย อ.เมืองเพชรบุรี จ.เพชรบุรี | D12: 063-9264461 | E12: 5500 | F12: 0 | G12: 0 | H12: 0 | I12: 8 | J12: 20 | K12: 211/0001-2569 | L12: 2026-05-01 00:00:00 | M12: ย้ายเข้า 1 พ.ค.69 | N12: 100
A13: 212 | B13: นายศุภาเดช ฉัตระเนตร | C13: 447/27 ถ.พลับพลาไชย แขวงป้อมปราบ เขตป้อมปราบศัตรูพ่าย กทม. | D13: 087-0835723 | E13: 4900 | F13: 0 | G13: 0 | H13: 0 | I13: 8 | J13: 20 | K13: 212/0005-2567 | L13: 2026-04-25 00:00:00 | N13: 100
A14: 213 | B14: นางสาวธัญภรณ์ ขวัญสกุล | C14: 552 ซ.พหลโยธิน87 ซอย 6 แยก 3 ต.ประชาธิปัตย์ อ.ธัญบุรี จ.ปทุมธานี | D14: 064-1610459 | E14: 5500 | F14: 0 | G14: 0 | H14: 0 | I14: 8 | J14: 20 | K14: 213/0001-2569 | L14: 2026-03-28 00:00:00 | N14: 100
A15: 214 | B15: นายธนพนธ์ อ้วนสุชาติ | C15: 63 ม.5 ต.หนองระเวียง อ.พิมาย จ.นครราชสีมา | D15: 085-8577164 | E15: 5000 | F15: 0 | G15: 0 | H15: 0 | I15: 8 | J15: 20 | K15: 214/0004-2567 | L15: 2024-12-09 00:00:00 | N15: 100
A16: 215 | B16: นางสาวณัฐวดี หอมเนียม | C16: 4 ม.1 ต.เฉนียง อ.เมือง จ.สุรินทร์ | D16: 064-1635591 | E16: 5000 | F16: 0 | G16: 0 | H16: 0 | I16: 8 | J16: 20 | K16: 215/0003-2568 | L16: 2025-05-06 00:00:00 | N16: 100
A17: 216 | B17: นายภูวรา อัคระนรากูล | C17: 30 ต.บางแคเหนือ อ.บางแค จ.กทม. | D17: 063-665-5465 | E17: 4500 | F17: 0 | G17: 0 | H17: 0 | I17: 8 | J17: 20 | K17: 216/0003-2564 | L17: 2021-03-04 00:00:00 | N17: 100
A18: 217 | B18: นายธนศักดิ์ ฤกษ์รัตนเศรษฐ์ | C18: โรงงานเทพศักดาอิฐประสาน 144 หมู่ 2 ต.เชื้อเพลง อ.ปราสาท จ.สุรินทร์ | D18: 094-3735152 | E18: 4500 | F18: 0 | G18: 250 | H18: 50 | I18: 5 | J18: 15 | K18: 217/0002-2560 | L18: 2017-09-01 00:00:00 | N18: 0
A19: 218 | B19: นางสาวพรรณปพร นันทอินทร์ | C19: 268 ถ.ป่าทม ต.หัวเวียง อ.เมือง จ.ลำปาง | D19: 065-9498831 | E19: 5500 | F19: 0 | G19: 0 | H19: 0 | I19: 8 | J19: 20 | K19: 201/0004-2566 | L19: 2025-10-26 00:00:00 | N19: 100
A20: 301 | B20: นางสาวประภาพร แก่นภูเลิศ | C20: 128 หมู่ที่ 16 ต.แสนสุข อ.วาริณชำราบ จ.อุบลราชธานี | D20: 065-9550919 | E20: 5500 | F20: 0 | G20: 0 | H20: 0 | I20: 8 | J20: 20 | K20: 301/0002-2569 | L20: 2026-01-30 00:00:00 | N20: 100
A21: 302 | B21: นางสาวศิริยาพร เพชรศรี | C21: 9 หมู่ที่ 7 ต.แป-ระ อ.ท่าแพ จ.สตูล | D21: 064-0915256 | E21: 5500 | F21: 0 | G21: 0 | H21: 0 | I21: 8 | J21: 20 | K21: 302/0001-2569 | L21: 2026-05-01 00:00:00 | M21: เข้า 1 พ.ค.69 | N21: 100
A22: 303 | B22: นางสาวรตินันท์ เพชรศรีช่วง | C22: 543 ถ.สมเด็จเจ้าพระยา แขวงคลองสาน เขตคลองสาน กทม | D22: 064-202-2525 | E22: 4900 | F22: 0 | G22: 250 | H22: 50 | I22: 5 | J22: 15 | K22: 303/0001-2560 | L22: 2024-12-01 00:00:00 | N22: 0
A23: 304 | B23: นางสาวปัทมพร ทูลธรรม | C23: 161 หมู่ที่ 1 ต.ปางกู่ อ.โนนสัง จ.หนองบัวลำภู | D23: 098-1432642 | E23: 5500 | F23: 0 | G23: 0 | H23: 0 | I23: 8 | J23: 20 | K23: 304/0002-2569 | L23: 2026-01-16 00:00:00 | N23: 100
A24: 305 | B24: นางสาวบัณฑิตา จันทร์พรหม | C24: 20 ม.6 ต.กระเฉด อ.เมือง จ.ระยอง | D24: 095-2695431 | E24: 5500 | F24: 0 | G24: 0 | H24: 0 | I24: 8 | J24: 20 | K24: 305/0007-2568 | L24: 2025-05-30 00:00:00 | N24: 100
A25: 306 | B25: นางสาวภูษิตา หล่อลีฬหา | C25: 19 ตรอกสุขมาศ ต.ในเมือง อ.เมืองนครราชศรีมา จ.นครราชศรีมา | D25: 063-0566162 | E25: 5500 | F25: 0 | G25: 0 | H25: 0 | I25: 8 | J25: 20 | K25: 306/0001-2569 | L25: 2026-05-04 00:00:00 | M25: เข้า 4 พ.ค.69 | N25: 100
A26: 307 | B26: นางสาวพัชรี พุทธรุฯณ | C26: 159 ม.8 ต.เวียง อ. เชียงคำ จ.พะเยา | D26: 061-5735125 | E26: 5500 | F26: 0 | G26: 0 | H26: 0 | I26: 8 | J26: 20 | K26: 307/0004-2568 | L26: 2025-08-10 00:00:00 | N26: 100
A27: 308 | B27: นางสาววีรวรรณ สังข์ทอง | C27: 117 ม. 5 ต.น้ำจืดน้อย อ.กระบุรี จ.ระนอง | D27: 084-4122517 | E27: 815 | F27: 0 | G27: 0 | H27: 0 | I27: 8 | J27: 20 | K27: 308/0005-2565 | L27: 2024-12-23 00:00:00 | N27: 100
A28: 309 | B28: นางสาวนวรัตน์ ศรีสงคราม | C28: 90 หมู่ที่ 1 ต.แก้งกอก อ.ศรีเมืองใหม่ จ.อุบลราชธานี | D28: 064-9148892 | E28: 5500 | F28: 0 | G28: 0 | H28: 0 | I28: 8 | J28: 20 | K28: 309/004-2562 | L28: 2025-09-29 00:00:00 | N28: 100
A29: 310 | B29: นางสาวปวีณ์ธิดา ต้นจันทน์ | C29: 208 ต.บางกระสอ อ.มือง จ.นนทบุรี | D29: 095-5086058 | E29: 5500 | F29: 0 | G29: 0 | H29: 0 | I29: 8 | J29: 20 | K29: 302/0006-2568 | L29: 2025-06-28 00:00:00 | N29: 100
A30: 311 | B30: นางสาวปนิตา เครือศิริ | C30: 237 ม.2 ต.บึงสามพัน อ.บึงสามพัน จเพชรบูรณ์ | D30: 648763713 | E30: 5500 | F30: 0 | G30: 0 | H30: 0 | I30: 8 | J30: 20 | K30: 311/0007-2568 | L30: 2025-03-30 00:00:00 | M30: ค่าเช่าตู้เย็น | N30: 100
A31: 312 | B31: นางสาวปิ่นนภา ยิ่งยงค์ | C31: 63 ม.4 ต.โพนยาง อ.วังหิน จ.ศรีสะเกษ | D31: 096-5099164 | E31: 5500 | F31: 0 | G31: 0 | H31: 0 | I31: 8 | J31: 20 | K31: 312/0005-2568 | L31: 2025-07-30 00:00:00 | N31: 100
A32: 313 | E32: 0 | F32: 0 | G32: 0 | H32: 0 | I32: 8 | J32: 20 | K32: 313/0003-2568 | M32: ออก 10 พ.ค.69 | N32: 100
A33: 314 | B33: นางสาวธัญวรัตน์ ฤทธิสาคร | C33: 42/3 หมู่ที่ 4 ต.ควนปริง อ.เมืองตรัง จ.ตรัง | D33: 082-2756970 | E33: 5500 | F33: 0 | G33: 0 | H33: 0 | I33: 8 | J33: 20 | K33: 314/0001-2569 | L33: 2026-03-30 00:00:00 | N33: 100
A34: 315 | B34: นางสาวพิชญ์สิตา ศุภศาสตร์วงศ์ | C34: 386/3 ต.โนนสูง อ.โนนสูง จ.นครราชสีมา | D34: 095-0309923 | E34: 5500 | F34: 0 | G34: 0 | H34: 0 | I34: 8 | J34: 20 | K34: 315/0004-2568 | L34: 2025-01-11 00:00:00 | M34: ค่าเช่าตู้เย็นเล็ก | N34: 100
A35: 316 | B35: นางสาวพรรณพัชร วราภรณ์ | C35: 15/3 ม.3 ต.ท่าซอม อ.หัวไทร จ.นครศรีธรรมราช | D35: 092-7696515 | E35: 4900 | F35: 0 | G35: 0 | H35: 0 | I35: 8 | J35: 20 | K35: 316/0003-2566 | L35: 2023-06-22 00:00:00 | N35: 100
A36: 317 | E36: 0 | F36: 0 | G36: 0 | H36: 0 | I36: 8 | J36: 20 | K36: 317/0002-2568 | N36: 100
A37: 318 | B37: นางสาวโยธิกานต์ ภิญโญ | C37: 53/4 หมู่ที่ 2 ตนาท่ามเหนือ อ.เมืองตรัง จ.ตรัง | D37: 089-6528780 | E37: 5500 | F37: 0 | G37: 0 | H37: 0 | I37: 8 | J37: 20 | K37: 318/0001-2569 | L37: 2026-03-31 00:00:00 | N37: 100
A38: 401 | B38: นายณัฐนันท์ อินทัศน์ | C38: 987/1 ต.ชะอำ อ.ชะอำ จ.เพชรบุรี | D38: 094-8059091 | E38: 5500 | F38: 0 | G38: 0 | H38: 0 | I38: 8 | J38: 20 | K38: 401/0004-2568 | L38: 2025-05-31 00:00:00 | N38: 100
A39: 402 | B39: shu jie | D39: 096-869-4864 | E39: 4900 | F39: 0 | G39: 0 | H39: 0 | I39: 8 | J39: 20 | K39: 402/0001-2560 | L39: 2017-04-21 00:00:00 | N39: 100
A40: 403 | B40: นายรัฐธรรมนูญ สังข์ไพฑูรย์ | C40: 4 หมู่ที่ 4 ต.ปากแตระ อ.ระโนด จ.สงขลา | D40: 063-5075237 | E40: 5500 | F40: 0 | G40: 0 | H40: 0 | I40: 8 | J40: 20 | K40: 403/0006-2568 | L40: 2025-12-28 00:00:00 | N40: 100
...
